[{"name": "unittest.loader._FailedTest.test.test_read_series", "status": "errored", "message": "Failed to import test module: test.test_read_series\nTraceback (most recent call last):\n  File \"/usr/lib/python3.10/unittest/loader.py\", line 436, in _find_test_path\n    module = self._get_module_from_name(name)\n  File \"/usr/lib/python3.10/unittest/loader.py\", line 377, in _get_module_from_name\n    __import__(name)\n  File \"/home/sonya/git/github/m1t0z/mooc-data-analysis-with-python-2021/part03-e13_read_series/test/test_read_series.py\", line 5, in <module>\n    import pandas\nModuleNotFoundError: No module named 'pandas'\n", "passed": false, "points": [], "backtrace": ["  File \"/usr/lib/python3.10/unittest/case.py\", line 59, in testPartExecutor\n    yield\n", "  File \"/usr/lib/python3.10/unittest/case.py\", line 591, in run\n    self._callTestMethod(testMethod)\n", "  File \"/usr/lib/python3.10/unittest/case.py\", line 549, in _callTestMethod\n    method()\n", "  File \"/usr/lib/python3.10/unittest/loader.py\", line 34, in testFailure\n    raise self._exception\n"]}]