[{"name": "test.test_first_half_second_half.FirstHalfSecondHalf.test_calls", "status": "failed", "message": "0 != 2 : Expected exactly two calls to function np.sum!", "passed": false, "points": ["p03-02.1"], "backtrace": ["  File \"/usr/lib/python3.10/unittest/case.py\", line 59, in testPartExecutor\n    yield\n", "  File \"/usr/lib/python3.10/unittest/case.py\", line 591, in run\n    self._callTestMethod(testMethod)\n", "  File \"/usr/lib/python3.10/unittest/case.py\", line 549, in _callTestMethod\n    method()\n", "  File \"/home/sonya/git/github/m1t0z/mooc-data-analysis-with-python-2021/part03-e02_first_half_second_half/test/test_first_half_second_half.py\", line 73, in test_calls\n    self.assertEqual(psum.call_count, 2, msg=\"Expected exactly two calls to function np.sum!\")\n"]}, {"name": "test.test_first_half_second_half.FirstHalfSecondHalf.test_content", "status": "passed", "message": "", "passed": true, "points": ["p03-02.1"], "backtrace": []}, {"name": "test.test_first_half_second_half.FirstHalfSecondHalf.test_shape", "status": "errored", "message": "tuple index out of range", "passed": false, "points": ["p03-02.1"], "backtrace": ["  File \"/usr/lib/python3.10/unittest/case.py\", line 59, in testPartExecutor\n    yield\n", "  File \"/usr/lib/python3.10/unittest/case.py\", line 591, in run\n    self._callTestMethod(testMethod)\n", "  File \"/usr/lib/python3.10/unittest/case.py\", line 549, in _callTestMethod\n    method()\n", "  File \"/home/sonya/git/github/m1t0z/mooc-data-analysis-with-python-2021/part03-e02_first_half_second_half/test/test_first_half_second_half.py\", line 45, in test_shape\n    self.assertEqual(result.shape[1], 2*m,\n"]}, {"name": "test.test_first_half_second_half.FirstHalfSecondHalf.test_simple", "status": "errored", "message": "tuple index out of range", "passed": false, "points": ["p03-02.1"], "backtrace": ["  File \"/usr/lib/python3.10/unittest/case.py\", line 59, in testPartExecutor\n    yield\n", "  File \"/usr/lib/python3.10/unittest/case.py\", line 591, in run\n    self._callTestMethod(testMethod)\n", "  File \"/usr/lib/python3.10/unittest/case.py\", line 549, in _callTestMethod\n    method()\n", "  File \"/home/sonya/git/github/m1t0z/mooc-data-analysis-with-python-2021/part03-e02_first_half_second_half/test/test_first_half_second_half.py\", line 55, in test_simple\n    self.assertEqual(result.shape[1], 2, msg=\"Incorrect number of columns for random array %s\" % a)\n"]}]