[{"name": "test.test_meeting_lines.MeetingLines.test_calls", "status": "failed", "message": "Expected 'solve' to have been called.", "passed": false, "points": ["p03-06.1"], "backtrace": ["  File \"/usr/lib/python3.10/unittest/case.py\", line 59, in testPartExecutor\n    yield\n", "  File \"/usr/lib/python3.10/unittest/case.py\", line 591, in run\n    self._callTestMethod(testMethod)\n", "  File \"/usr/lib/python3.10/unittest/case.py\", line 549, in _callTestMethod\n    method()\n", "  File \"/home/sonya/git/github/m1t0z/mooc-data-analysis-with-python-2021/part03-e06_meeting_lines/test/test_meeting_lines.py\", line 36, in test_calls\n    psolve.assert_called()\n", "  File \"/usr/lib/python3.10/unittest/mock.py\", line 888, in assert_called\n    raise AssertionError(msg)\n"]}, {"name": "test.test_meeting_lines.MeetingLines.test_first", "status": "errored", "message": "not enough values to unpack (expected 2, got 0)", "passed": false, "points": ["p03-06.1"], "backtrace": ["  File \"/usr/lib/python3.10/unittest/case.py\", line 59, in testPartExecutor\n    yield\n", "  File \"/usr/lib/python3.10/unittest/case.py\", line 591, in run\n    self._callTestMethod(testMethod)\n", "  File \"/usr/lib/python3.10/unittest/case.py\", line 549, in _callTestMethod\n    method()\n", "  File \"/home/sonya/git/github/m1t0z/mooc-data-analysis-with-python-2021/part03-e06_meeting_lines/test/test_meeting_lines.py\", line 24, in test_first\n    x, y = meeting_lines(a1,b1,a2,b2)\n"]}, {"name": "test.test_meeting_lines.MeetingLines.test_inconsistent", "status": "failed", "message": "LinAlgError not raised : Inconsistent system (a1=1, b1=4, a2=1, b2=4) should raise an exception!", "passed": false, "points": ["p03-06.1"], "backtrace": ["  File \"/usr/lib/python3.10/unittest/case.py\", line 59, in testPartExecutor\n    yield\n", "  File \"/usr/lib/python3.10/unittest/case.py\", line 591, in run\n    self._callTestMethod(testMethod)\n", "  File \"/usr/lib/python3.10/unittest/case.py\", line 549, in _callTestMethod\n    method()\n", "  File \"/home/sonya/git/github/m1t0z/mooc-data-analysis-with-python-2021/part03-e06_meeting_lines/test/test_meeting_lines.py\", line 52, in test_inconsistent\n    with self.assertRaises(np.linalg.linalg.LinAlgError,\n"]}, {"name": "test.test_meeting_lines.MeetingLines.test_underdetermined", "status": "failed", "message": "LinAlgError not raised : Under determined system (a1=1, b1=4, a2=1, b2=4) should raise an exception!", "passed": false, "points": ["p03-06.1"], "backtrace": ["  File \"/usr/lib/python3.10/unittest/case.py\", line 59, in testPartExecutor\n    yield\n", "  File \"/usr/lib/python3.10/unittest/case.py\", line 591, in run\n    self._callTestMethod(testMethod)\n", "  File \"/usr/lib/python3.10/unittest/case.py\", line 549, in _callTestMethod\n    method()\n", "  File \"/home/sonya/git/github/m1t0z/mooc-data-analysis-with-python-2021/part03-e06_meeting_lines/test/test_meeting_lines.py\", line 43, in test_underdetermined\n    with self.assertRaises(np.linalg.linalg.LinAlgError,\n"]}]