[{"name": "test.test_multiplication_table_revisited.MultiplicationTableRevisited.test_calls", "status": "failed", "message": "Expected 'arange' to have been called.", "passed": false, "points": ["p02-16.1"], "backtrace": ["  File \"/usr/lib/python3.10/unittest/case.py\", line 59, in testPartExecutor\n    yield\n", "  File \"/usr/lib/python3.10/unittest/case.py\", line 591, in run\n    self._callTestMethod(testMethod)\n", "  File \"/usr/lib/python3.10/unittest/case.py\", line 549, in _callTestMethod\n    method()\n", "  File \"/home/sonya/git/github/m1t0z/mooc-data-analysis-with-python-2021/part02-e16_multiplication_table_revisited/test/test_multiplication_table_revisited.py\", line 50, in test_calls\n    parange.assert_called()\n", "  File \"/usr/lib/python3.10/unittest/mock.py\", line 888, in assert_called\n    raise AssertionError(msg)\n"]}, {"name": "test.test_multiplication_table_revisited.MultiplicationTableRevisited.test_content", "status": "failed", "message": "Tuples differ: (0,) != (1, 1)\n\nFirst differing element 0:\n0\n1\n\nSecond tuple contains 1 additional elements.\nFirst extra element 1:\n1\n\n- (0,)\n+ (1, 1) : Incorrect shape!", "passed": false, "points": ["p02-16.1"], "backtrace": ["  File \"/usr/lib/python3.10/unittest/case.py\", line 59, in testPartExecutor\n    yield\n", "  File \"/usr/lib/python3.10/unittest/case.py\", line 591, in run\n    self._callTestMethod(testMethod)\n", "  File \"/usr/lib/python3.10/unittest/case.py\", line 549, in _callTestMethod\n    method()\n", "  File \"/home/sonya/git/github/m1t0z/mooc-data-analysis-with-python-2021/part02-e16_multiplication_table_revisited/test/test_multiplication_table_revisited.py\", line 43, in test_content\n    self.assertEqual(a.shape, (n,n), msg=\"Incorrect shape!\")\n"]}]