[{"name": "test.test_prepend.PrependTest.test_first", "status": "failed", "message": "+++ ", "passed": false, "points": ["p02-08.1"], "backtrace": ["  File \"/usr/lib/python3.10/unittest/case.py\", line 59, in testPartExecutor\n    yield\n", "  File \"/usr/lib/python3.10/unittest/case.py\", line 591, in run\n    self._callTestMethod(testMethod)\n", "  File \"/usr/lib/python3.10/unittest/case.py\", line 549, in _callTestMethod\n    method()\n", "  File \"/home/sonya/git/github/m1t0z/mooc-data-analysis-with-python-2021/part02-e08_prepend/test/test_prepend.py\", line 18, in test_first\n    p = Prepend(\"+++ \")\n", "  File \"/home/sonya/git/github/m1t0z/mooc-data-analysis-with-python-2021/part02-e08_prepend/tmc/utils.py\", line 79, in fail\n    raise AssertionError(args[0])\n"]}]