[{"name": "test.test_summary.Summary.test_calls", "status": "failed", "message": "Expected 'open' to have been called.", "passed": false, "points": ["p02-05.1"], "backtrace": ["  File \"/usr/lib/python3.10/unittest/case.py\", line 59, in testPartExecutor\n    yield\n", "  File \"/usr/lib/python3.10/unittest/case.py\", line 591, in run\n    self._callTestMethod(testMethod)\n", "  File \"/usr/lib/python3.10/unittest/case.py\", line 549, in _callTestMethod\n    method()\n", "  File \"/home/sonya/git/github/m1t0z/mooc-data-analysis-with-python-2021/part02-e05_summary/test/test_summary.py\", line 50, in test_calls\n    o.assert_called()\n", "  File \"/usr/lib/python3.10/unittest/mock.py\", line 888, in assert_called\n    raise AssertionError(msg)\n"]}, {"name": "test.test_summary.Summary.test_main", "status": "failed", "message": "0 != 7 : Expected 7 calls to summary for 7 command line parameters!", "passed": false, "points": ["p02-05.1"], "backtrace": ["  File \"/usr/lib/python3.10/unittest/case.py\", line 59, in testPartExecutor\n    yield\n", "  File \"/usr/lib/python3.10/unittest/case.py\", line 591, in run\n    self._callTestMethod(testMethod)\n", "  File \"/usr/lib/python3.10/unittest/case.py\", line 549, in _callTestMethod\n    method()\n", "  File \"/home/sonya/git/github/m1t0z/mooc-data-analysis-with-python-2021/part02-e05_summary/test/test_summary.py\", line 60, in test_main\n    self.assertEqual(s.call_count, n,\n"]}, {"name": "test.test_summary.Summary.test_missing_file", "status": "failed", "message": "FileNotFoundError not raised", "passed": false, "points": ["p02-05.1"], "backtrace": ["  File \"/usr/lib/python3.10/unittest/case.py\", line 59, in testPartExecutor\n    yield\n", "  File \"/usr/lib/python3.10/unittest/case.py\", line 591, in run\n    self._callTestMethod(testMethod)\n", "  File \"/usr/lib/python3.10/unittest/case.py\", line 549, in _callTestMethod\n    method()\n", "  File \"/home/sonya/git/github/m1t0z/mooc-data-analysis-with-python-2021/part02-e05_summary/test/test_summary.py\", line 43, in test_missing_file\n    with self.assertRaises(FileNotFoundError):\n"]}, {"name": "test.test_summary.Summary.test_one", "status": "failed", "message": "0 != 51.4 within 4 places (51.4 difference) : Wrong sum for file example.txt!", "passed": false, "points": ["p02-05.1"], "backtrace": ["  File \"/usr/lib/python3.10/unittest/case.py\", line 59, in testPartExecutor\n    yield\n", "  File \"/usr/lib/python3.10/unittest/case.py\", line 591, in run\n    self._callTestMethod(testMethod)\n", "  File \"/usr/lib/python3.10/unittest/case.py\", line 549, in _callTestMethod\n    method()\n", "  File \"/home/sonya/git/github/m1t0z/mooc-data-analysis-with-python-2021/part02-e05_summary/test/test_summary.py\", line 23, in test_one\n    self.assertAlmostEqual(s, 51.400000, places=4, msg=\"Wrong sum for file example.txt!\")\n"]}, {"name": "test.test_summary.Summary.test_three", "status": "failed", "message": "0 != 50.0 within 4 places (50.0 difference) : Wrong std for file example3.txt!", "passed": false, "points": ["p02-05.2"], "backtrace": ["  File \"/usr/lib/python3.10/unittest/case.py\", line 59, in testPartExecutor\n    yield\n", "  File \"/usr/lib/python3.10/unittest/case.py\", line 591, in run\n    self._callTestMethod(testMethod)\n", "  File \"/usr/lib/python3.10/unittest/case.py\", line 549, in _callTestMethod\n    method()\n", "  File \"/home/sonya/git/github/m1t0z/mooc-data-analysis-with-python-2021/part02-e05_summary/test/test_summary.py\", line 39, in test_three\n    self.assertAlmostEqual(d, 50.000000, places=4, msg=\"Wrong std for file example3.txt!\")\n"]}, {"name": "test.test_summary.Summary.test_two", "status": "failed", "message": "0 != 5446.2 within 4 places (5446.2 difference) : Wrong sum for file example2.txt!", "passed": false, "points": ["p02-05.1"], "backtrace": ["  File \"/usr/lib/python3.10/unittest/case.py\", line 59, in testPartExecutor\n    yield\n", "  File \"/usr/lib/python3.10/unittest/case.py\", line 591, in run\n    self._callTestMethod(testMethod)\n", "  File \"/usr/lib/python3.10/unittest/case.py\", line 549, in _callTestMethod\n    method()\n", "  File \"/home/sonya/git/github/m1t0z/mooc-data-analysis-with-python-2021/part02-e05_summary/test/test_summary.py\", line 30, in test_two\n    self.assertAlmostEqual(s, 5446.200000, places=4, msg=\"Wrong sum for file example2.txt!\")\n"]}]