[{"name": "test.test_meeting_planes.MeetingPlanes.test_calls", "status": "failed", "message": "Expected 'solve' to have been called once. Called 0 times.", "passed": false, "points": ["p03-07.1"], "backtrace": ["  File \"/usr/lib/python3.10/unittest/case.py\", line 59, in testPartExecutor\n    yield\n", "  File \"/usr/lib/python3.10/unittest/case.py\", line 591, in run\n    self._callTestMethod(testMethod)\n", "  File \"/usr/lib/python3.10/unittest/case.py\", line 549, in _callTestMethod\n    method()\n", "  File \"/home/sonya/git/github/m1t0z/mooc-data-analysis-with-python-2021/part03-e07_meeting_planes/test/test_meeting_planes.py\", line 61, in test_calls\n    psolve.assert_called_once()\n", "  File \"/usr/lib/python3.10/unittest/mock.py\", line 898, in assert_called_once\n    raise AssertionError(msg)\n"]}, {"name": "test.test_meeting_planes.MeetingPlanes.test_first", "status": "errored", "message": "not enough values to unpack (expected 3, got 0)", "passed": false, "points": ["p03-07.1"], "backtrace": ["  File \"/usr/lib/python3.10/unittest/case.py\", line 59, in testPartExecutor\n    yield\n", "  File \"/usr/lib/python3.10/unittest/case.py\", line 591, in run\n    self._callTestMethod(testMethod)\n", "  File \"/usr/lib/python3.10/unittest/case.py\", line 549, in _callTestMethod\n    method()\n", "  File \"/home/sonya/git/github/m1t0z/mooc-data-analysis-with-python-2021/part03-e07_meeting_planes/test/test_meeting_planes.py\", line 38, in test_first\n    x, y, z = meeting_planes(a1, b1, c1,\n"]}, {"name": "test.test_meeting_planes.MeetingPlanes.test_inconsistent", "status": "failed", "message": "LinAlgError not raised : Inconsistent system (a1=1, b1=4, c1=2, a2=1, b2=4, c2=2, a3=1, b3=4, c3=3) should raise an exception!", "passed": false, "points": ["p03-07.1"], "backtrace": ["  File \"/usr/lib/python3.10/unittest/case.py\", line 59, in testPartExecutor\n    yield\n", "  File \"/usr/lib/python3.10/unittest/case.py\", line 591, in run\n    self._callTestMethod(testMethod)\n", "  File \"/usr/lib/python3.10/unittest/case.py\", line 549, in _callTestMethod\n    method()\n", "  File \"/home/sonya/git/github/m1t0z/mooc-data-analysis-with-python-2021/part03-e07_meeting_planes/test/test_meeting_planes.py\", line 84, in test_inconsistent\n    with self.assertRaises(np.linalg.linalg.LinAlgError,\n"]}, {"name": "test.test_meeting_planes.MeetingPlanes.test_underdetermined", "status": "failed", "message": "LinAlgError not raised : Under determined system (a1=1, b1=4, c1=2, a2=1, b2=4, c2=2, a3=1, b3=4, c3=2) should raise an exception!", "passed": false, "points": ["p03-07.1"], "backtrace": ["  File \"/usr/lib/python3.10/unittest/case.py\", line 59, in testPartExecutor\n    yield\n", "  File \"/usr/lib/python3.10/unittest/case.py\", line 591, in run\n    self._callTestMethod(testMethod)\n", "  File \"/usr/lib/python3.10/unittest/case.py\", line 549, in _callTestMethod\n    method()\n", "  File \"/home/sonya/git/github/m1t0z/mooc-data-analysis-with-python-2021/part03-e07_meeting_planes/test/test_meeting_planes.py\", line 71, in test_underdetermined\n    with self.assertRaises(np.linalg.linalg.LinAlgError,\n"]}]