[{"name": "test.test_inverse_series.InverseSeries.test_called", "status": "failed", "message": "Expected 'inverse_series' to have been called.", "passed": false, "points": ["p03-15.1"], "backtrace": ["  File \"/usr/lib/python3.10/unittest/case.py\", line 59, in testPartExecutor\n    yield\n", "  File \"/usr/lib/python3.10/unittest/case.py\", line 591, in run\n    self._callTestMethod(testMethod)\n", "  File \"/usr/lib/python3.10/unittest/case.py\", line 549, in _callTestMethod\n    method()\n", "  File \"/home/sonya/git/github/m1t0z/mooc-data-analysis-with-python-2021/part03-e15_inverse_series/test/test_inverse_series.py\", line 45, in test_called\n    pis.assert_called()\n", "  File \"/usr/lib/python3.10/unittest/mock.py\", line 888, in assert_called\n    raise AssertionError(msg)\n"]}, {"name": "test.test_inverse_series.InverseSeries.test_empty", "status": "passed", "message": "", "passed": true, "points": ["p03-15.1"], "backtrace": []}, {"name": "test.test_inverse_series.InverseSeries.test_first", "status": "failed", "message": "\nArrays are not equal\nValues were incorrect!\n(shapes (0,), (4,) mismatch)\n x: array([], dtype=float64)\n y: array(['a', 'b', 'c', 'd'], dtype='<U1')", "passed": false, "points": ["p03-15.1"], "backtrace": ["  File \"/usr/lib/python3.10/unittest/case.py\", line 59, in testPartExecutor\n    yield\n", "  File \"/usr/lib/python3.10/unittest/case.py\", line 591, in run\n    self._callTestMethod(testMethod)\n", "  File \"/usr/lib/python3.10/unittest/case.py\", line 549, in _callTestMethod\n    method()\n", "  File \"/home/sonya/git/github/m1t0z/mooc-data-analysis-with-python-2021/part03-e15_inverse_series/test/test_inverse_series.py\", line 26, in test_first\n    np.testing.assert_array_equal(t.values, ind, err_msg=\"Values were incorrect!\")\n", "  File \"/home/sonya/.local/lib/python3.10/site-packages/numpy/testing/_private/utils.py\", line 934, in assert_array_equal\n    assert_array_compare(operator.__eq__, x, y, err_msg=err_msg,\n", "  File \"/home/sonya/.local/lib/python3.10/site-packages/numpy/testing/_private/utils.py\", line 763, in assert_array_compare\n    raise AssertionError(msg)\n"]}, {"name": "test.test_inverse_series.InverseSeries.test_second", "status": "failed", "message": "\nArrays are not equal\nValues were incorrect!\n(shapes (0,), (4,) mismatch)\n x: array([], dtype=float64)\n y: array(['a', 'b', 'c', 'd'], dtype='<U1')", "passed": false, "points": ["p03-15.1"], "backtrace": ["  File \"/usr/lib/python3.10/unittest/case.py\", line 59, in testPartExecutor\n    yield\n", "  File \"/usr/lib/python3.10/unittest/case.py\", line 591, in run\n    self._callTestMethod(testMethod)\n", "  File \"/usr/lib/python3.10/unittest/case.py\", line 549, in _callTestMethod\n    method()\n", "  File \"/home/sonya/git/github/m1t0z/mooc-data-analysis-with-python-2021/part03-e15_inverse_series/test/test_inverse_series.py\", line 34, in test_second\n    np.testing.assert_array_equal(t.values, ind, err_msg=\"Values were incorrect!\")\n", "  File \"/home/sonya/.local/lib/python3.10/site-packages/numpy/testing/_private/utils.py\", line 934, in assert_array_equal\n    assert_array_compare(operator.__eq__, x, y, err_msg=err_msg,\n", "  File \"/home/sonya/.local/lib/python3.10/site-packages/numpy/testing/_private/utils.py\", line 763, in assert_array_compare\n    raise AssertionError(msg)\n"]}]