[{"name": "test.test_correlation.Correlation.test_correlations", "status": "errored", "message": "not enough values to unpack (expected 2, got 1)", "passed": false, "points": ["p03-05.2"], "backtrace": ["  File \"/usr/lib/python3.10/unittest/case.py\", line 59, in testPartExecutor\n    yield\n", "  File \"/usr/lib/python3.10/unittest/case.py\", line 591, in run\n    self._callTestMethod(testMethod)\n", "  File \"/usr/lib/python3.10/unittest/case.py\", line 549, in _callTestMethod\n    method()\n", "  File \"/home/sonya/git/github/m1t0z/mooc-data-analysis-with-python-2021/part03-e05_correlation/test/test_correlation.py\", line 54, in test_correlations\n    n, m = result.shape\n"]}, {"name": "test.test_correlation.Correlation.test_lengths", "status": "failed", "message": "0 != 0.8717537758865832 within 4 places (0.8717537758865832 difference) : Wrong correlation!", "passed": false, "points": ["p03-05.1"], "backtrace": ["  File \"/usr/lib/python3.10/unittest/case.py\", line 59, in testPartExecutor\n    yield\n", "  File \"/usr/lib/python3.10/unittest/case.py\", line 591, in run\n    self._callTestMethod(testMethod)\n", "  File \"/usr/lib/python3.10/unittest/case.py\", line 549, in _callTestMethod\n    method()\n", "  File \"/home/sonya/git/github/m1t0z/mooc-data-analysis-with-python-2021/part03-e05_correlation/test/test_correlation.py\", line 42, in test_lengths\n    self.assertAlmostEqual(result, 0.8717537758865832, places=4, msg=\"Wrong correlation!\")\n"]}, {"name": "test.test_correlation.Correlation.test_lengths_calls", "status": "failed", "message": "Expected 'corrcoef' to have been called.", "passed": false, "points": ["p03-05.1", "p03-05.2"], "backtrace": ["  File \"/usr/lib/python3.10/unittest/case.py\", line 59, in testPartExecutor\n    yield\n", "  File \"/usr/lib/python3.10/unittest/case.py\", line 591, in run\n    self._callTestMethod(testMethod)\n", "  File \"/usr/lib/python3.10/unittest/case.py\", line 549, in _callTestMethod\n    method()\n", "  File \"/home/sonya/git/github/m1t0z/mooc-data-analysis-with-python-2021/part03-e05_correlation/test/test_correlation.py\", line 78, in test_lengths_calls\n    pcorr.assert_called()\n", "  File \"/usr/lib/python3.10/unittest/mock.py\", line 888, in assert_called\n    raise AssertionError(msg)\n"]}]