[{"name": "test.test_operations_on_series.OperationsOnSeries.test_creation", "status": "errored", "message": "module 'src.operations_on_series' has no attribute 'pd'", "passed": false, "points": ["p03-14.1"], "backtrace": ["  File \"/usr/lib/python3.10/unittest/case.py\", line 59, in testPartExecutor\n    yield\n", "  File \"/usr/lib/python3.10/unittest/case.py\", line 591, in run\n    self._callTestMethod(testMethod)\n", "  File \"/usr/lib/python3.10/unittest/case.py\", line 549, in _callTestMethod\n    method()\n", "  File \"/home/sonya/git/github/m1t0z/mooc-data-analysis-with-python-2021/part03-e14_operations_on_series/test/test_operations_on_series.py\", line 28, in test_creation\n    with patch(ph(\"pd.Series\"), wraps=pd.Series) as ps:\n", "  File \"/home/sonya/git/github/m1t0z/mooc-data-analysis-with-python-2021/part03-e14_operations_on_series/tmc/utils.py\", line 216, in __call__\n    getattr(importlib.import_module(self.m), parts[-2])  # subpackage2.attribute\n"]}, {"name": "test.test_operations_on_series.OperationsOnSeries.test_main", "status": "errored", "message": "module 'src.operations_on_series' has no attribute 'pd'", "passed": false, "points": ["p03-14.1"], "backtrace": ["  File \"/usr/lib/python3.10/unittest/case.py\", line 59, in testPartExecutor\n    yield\n", "  File \"/usr/lib/python3.10/unittest/case.py\", line 591, in run\n    self._callTestMethod(testMethod)\n", "  File \"/usr/lib/python3.10/unittest/case.py\", line 549, in _callTestMethod\n    method()\n", "  File \"/home/sonya/git/github/m1t0z/mooc-data-analysis-with-python-2021/part03-e14_operations_on_series/test/test_operations_on_series.py\", line 68, in test_main\n    patch(ph(\"pd.Series.__add__\"), side_effect=[pd.Series()]) as padd,\\\n", "  File \"/home/sonya/git/github/m1t0z/mooc-data-analysis-with-python-2021/part03-e14_operations_on_series/tmc/utils.py\", line 223, in __call__\n    getattr(importlib.import_module(self.m), parts[-3])  # subpackage.subpackage2.attribute\n"]}, {"name": "test.test_operations_on_series.OperationsOnSeries.test_modification", "status": "failed", "message": "None is not an instance of <class 'pandas.core.series.Series'> : Expected modify_series to return a pair of Series!", "passed": false, "points": ["p03-14.1"], "backtrace": ["  File \"/usr/lib/python3.10/unittest/case.py\", line 59, in testPartExecutor\n    yield\n", "  File \"/usr/lib/python3.10/unittest/case.py\", line 591, in run\n    self._callTestMethod(testMethod)\n", "  File \"/usr/lib/python3.10/unittest/case.py\", line 549, in _callTestMethod\n    method()\n", "  File \"/home/sonya/git/github/m1t0z/mooc-data-analysis-with-python-2021/part03-e14_operations_on_series/test/test_operations_on_series.py\", line 52, in test_modification\n    self.assertIsInstance(t1, pd.Series, msg=\"Expected modify_series to return a pair of Series!\")\n"]}]